Workbook

Sheet Grimm et al. (2015)
A1: Core | B1: Depth (m) | C1: Temp © | D1: eps_inf | E1: delta_eps1 | F1: fr1 (Hz) | G1: alpha1 | H1: delta_eps2 | I1: fr2 (Hz) | J1: alpha2 | K1: sigmaDC | L1: Ea1 | M1: Ea2 | N1: delta_eps1>delta_eps2 | O1: f1>f2 | P1: alpha1>alpha2 | Q1: Ea1>Ea2 | R1: sigma_inf1 | S1: sigma_inf2 | T1: sigma_inf1>sigma_inf2
A2: Fremont | B2: 3.96 | C2: -40.8 | D2: 3.24 | E2: 137.72 | F2: 720.4 | G2: 0 | H2: n/a | I2: n/a | J2: n/a | K2: 3.2e-09 | L2: 0.151 | M2: n/a | N2: =IF(H2="n/a","n/a",IF(E2>H2,1,0)) -> n/a | O2: =IF(I2="n/a","n/a",IF(F2>I2,1,0)) -> n/a | P2: =IF(J2="n/a","n/a",IF(G2>J2,1,0)) -> n/a | Q2: =IF(M2="n/a","n/a",IF(L2>M2,1,0)) -> n/a | R2: =E2*F2 -> 99213.488 | S2: =IF(H2="n/a","n/a",H2*I2) -> n/a | T2: =IF(S2="n/a","n/a",IF(R2>S2,1,0)) -> n/a
A3: Fremont | B3: 13.46 | C3: -40.7 | D3: 2.83 | E3: 18.8 | F3: 2460 | G3: 0.298 | H3: 9.68 | I3: 623.83 | J3: 0.018 | K3: 1.1e-11 | L3: 0.1649 | M3: 0.1462 | N3: =IF(H3="n/a","n/a",IF(E3>H3,1,0)) -> 1 | O3: =IF(I3="n/a","n/a",IF(F3>I3,1,0)) -> 1 | P3: =IF(J3="n/a","n/a",IF(G3>J3,1,0)) -> 1 | Q3: =IF(M3="n/a","n/a",IF(L3>M3,1,0)) -> 1 | R3: =E3*F3 -> 46248 | S3: =IF(H3="n/a","n/a",H3*I3) -> 6038.6744 | T3: =IF(S3="n/a","n/a",IF(R3>S3,1,0)) -> 1
A4: Fremont | B4: 74.24 | C4: -40.6 | D4: 3.04 | E4: 46.8 | F4: 313.27 | G4: 0.0097 | H4: n/a | I4: n/a | J4: n/a | K4: 1.73e-09 | L4: 0.1495 | M4: n/a | N4: =IF(H4="n/a","n/a",IF(E4>H4,1,0)) -> n/a | O4: =IF(I4="n/a","n/a",IF(F4>I4,1,0)) -> n/a | P4: =IF(J4="n/a","n/a",IF(G4>J4,1,0)) -> n/a | Q4: =IF(M4="n/a","n/a",IF(L4>M4,1,0)) -> n/a | R4: =E4*F4 -> 14661.036 | S4: =IF(H4="n/a","n/a",H4*I4) -> n/a | T4: =IF(S4="n/a","n/a",IF(R4>S4,1,0)) -> n/a
A5: Fremont | B5: 137.92 | C5: -40.7 | D5: 3.05 | E5: 51.71 | F5: 204 | G5: 0 | H5: n/a | I5: n/a | J5: n/a | K5: 6.44e-10 | L5: 0.2053 | M5: n/a | N5: =IF(H5="n/a","n/a",IF(E5>H5,1,0)) -> n/a | O5: =IF(I5="n/a","n/a",IF(F5>I5,1,0)) -> n/a | P5: =IF(J5="n/a","n/a",IF(G5>J5,1,0)) -> n/a | Q5: =IF(M5="n/a","n/a",IF(L5>M5,1,0)) -> n/a | R5: =E5*F5 -> 10548.84 | S5: =IF(H5="n/a","n/a",H5*I5) -> n/a | T5: =IF(S5="n/a","n/a",IF(R5>S5,1,0)) -> n/a
A6: Mullins | B6: 8.6 | C6: -40.2 | D6: 2.88 | E6: 125.3 | F6: 1360 | G6: 0.0359 | H6: n/a | I6: n/a | J6: n/a | K6: 2.3e-08 | L6: 0.1653 | M6: 0.55 | N6: =IF(H6="n/a","n/a",IF(E6>H6,1,0)) -> n/a | O6: =IF(I6="n/a","n/a",IF(F6>I6,1,0)) -> n/a | P6: =IF(J6="n/a","n/a",IF(G6>J6,1,0)) -> n/a | Q6: =IF(M6="n/a","n/a",IF(L6>M6,1,0)) -> 0 | R6: =E6*F6 -> 170408 | S6: =IF(H6="n/a","n/a",H6*I6) -> n/a | T6: =IF(S6="n/a","n/a",IF(R6>S6,1,0)) -> n/a
A7: Mullins | B7: 1.27 | C7: -40.3 | D7: 2.73 | E7: 30.85 | F7: 1580 | G7: 0.0342 | H7: n/a | I7: n/a | J7: n/a | K7: 1.32e-10 | L7: 0.1906 | M7: n/a | N7: =IF(H7="n/a","n/a",IF(E7>H7,1,0)) -> n/a | O7: =IF(I7="n/a","n/a",IF(F7>I7,1,0)) -> n/a | P7: =IF(J7="n/a","n/a",IF(G7>J7,1,0)) -> n/a | Q7: =IF(M7="n/a","n/a",IF(L7>M7,1,0)) -> n/a | R7: =E7*F7 -> 48743 | S7: =IF(H7="n/a","n/a",H7*I7) -> n/a | T7: =IF(S7="n/a","n/a",IF(R7>S7,1,0)) -> n/a
A8: Mullins | B8: 0.25 | C8: -40.4 | D8: 2.97 | E8: 81.52 | F8: 8250 | G8: 0.003 | H8: n/a | I8: n/a | J8: n/a | K8: 3.8e-10 | L8: 0.251 | M8: n/a | N8: =IF(H8="n/a","n/a",IF(E8>H8,1,0)) -> n/a | O8: =IF(I8="n/a","n/a",IF(F8>I8,1,0)) -> n/a | P8: =IF(J8="n/a","n/a",IF(G8>J8,1,0)) -> n/a | Q8: =IF(M8="n/a","n/a",IF(L8>M8,1,0)) -> n/a | R8: =E8*F8 -> 672540 | S8: =IF(H8="n/a","n/a",H8*I8) -> n/a | T8: =IF(S8="n/a","n/a",IF(R8>S8,1,0)) -> n/a
A9: Mullins | B9: 0.37 | C9: -40.3 | D9: 2.91 | E9: 44.82 | F9: 10700 | G9: 0.1214 | H9: n/a | I9: n/a | J9: n/a | K9: 5.78e-10 | L9: 0.2789 | M9: n/a | N9: =IF(H9="n/a","n/a",IF(E9>H9,1,0)) -> n/a | O9: =IF(I9="n/a","n/a",IF(F9>I9,1,0)) -> n/a | P9: =IF(J9="n/a","n/a",IF(G9>J9,1,0)) -> n/a | Q9: =IF(M9="n/a","n/a",IF(L9>M9,1,0)) -> n/a | R9: =E9*F9 -> 479574 | S9: =IF(H9="n/a","n/a",H9*I9) -> n/a | T9: =IF(S9="n/a","n/a",IF(R9>S9,1,0)) -> n/a
A10: Mullins | B10: 0.7 | C10: -41.4 | D10: 2.72 | E10: 37.58 | F10: 9590 | G10: 0.034 | H10: n/a | I10: n/a | J10: n/a | K10: 7.46e-10 | L10: 0.2011 | M10: n/a | N10: =IF(H10="n/a","n/a",IF(E10>H10,1,0)) -> n/a | O10: =IF(I10="n/a","n/a",IF(F10>I10,1,0)) -> n/a | P10: =IF(J10="n/a","n/a",IF(G10>J10,1,0)) -> n/a | Q10: =IF(M10="n/a","n/a",IF(L10>M10,1,0)) -> n/a | R10: =E10*F10 -> 360392.2 | S10: =IF(H10="n/a","n/a",H10*I10) -> n/a | T10: =IF(S10="n/a","n/a",IF(R10>S10,1,0)) -> n/a
A11: Mullins | B11: 5.98 | C11: -41.3 | D11: 2.98 | E11: 119.2 | F11: 2570 | G11: 0.021 | H11: n/a | I11: n/a | J11: n/a | K11: 6.22e-10 | L11: 0.234 | M11: n/a | N11: =IF(H11="n/a","n/a",IF(E11>H11,1,0)) -> n/a | O11: =IF(I11="n/a","n/a",IF(F11>I11,1,0)) -> n/a | P11: =IF(J11="n/a","n/a",IF(G11>J11,1,0)) -> n/a | Q11: =IF(M11="n/a","n/a",IF(L11>M11,1,0)) -> n/a | R11: =E11*F11 -> 306344 | S11: =IF(H11="n/a","n/a",H11*I11) -> n/a | T11: =IF(S11="n/a","n/a",IF(R11>S11,1,0)) -> n/a
A12: Mullins | B12: 15.34 | C12: -42 | D12: 2.61 | E12: 8.07 | F12: 9810 | G12: 0 | H12: 18.8 | I12: 2410 | J12: 0 | K12: 4.5e-11 | L12: 0.1592 | M12: 0.174 | N12: =IF(H12="n/a","n/a",IF(E12>H12,1,0)) -> 0 | O12: =IF(I12="n/a","n/a",IF(F12>I12,1,0)) -> 1 | P12: =IF(J12="n/a","n/a",IF(G12>J12,1,0)) -> 0 | Q12: =IF(M12="n/a","n/a",IF(L12>M12,1,0)) -> 0 | R12: =E12*F12 -> 79166.7 | S12: =IF(H12="n/a","n/a",H12*I12) -> 45308 | T12: =IF(S12="n/a","n/a",IF(R12>S12,1,0)) -> 1
A13: Mullins | B13: 16.18 | C13: -40.9 | D13: 2.98 | E13: 50.53 | F13: 6200 | G13: 0 | H13: n/a | I13: n/a | J13: n/a | K13: 3.71e-10 | L13: 0.262 | M13: n/a | N13: =IF(H13="n/a","n/a",IF(E13>H13,1,0)) -> n/a | O13: =IF(I13="n/a","n/a",IF(F13>I13,1,0)) -> n/a | P13: =IF(J13="n/a","n/a",IF(G13>J13,1,0)) -> n/a | Q13: =IF(M13="n/a","n/a",IF(L13>M13,1,0)) -> n/a | R13: =E13*F13 -> 313286 | S13: =IF(H13="n/a","n/a",H13*I13) -> n/a | T13: =IF(S13="n/a","n/a",IF(R13>S13,1,0)) -> n/a
A14: Mullins | B14: 16.5 | C14: -40.3 | D14: 2.88 | E14: 94.5 | F14: 1710 | G14: 0.03 | H14: n/a | I14: n/a | J14: n/a | K14: 1.17e-10 | L14: 0.2035 | M14: n/a | N14: =IF(H14="n/a","n/a",IF(E14>H14,1,0)) -> n/a | O14: =IF(I14="n/a","n/a",IF(F14>I14,1,0)) -> n/a | P14: =IF(J14="n/a","n/a",IF(G14>J14,1,0)) -> n/a | Q14: =IF(M14="n/a","n/a",IF(L14>M14,1,0)) -> n/a | R14: =E14*F14 -> 161595 | S14: =IF(H14="n/a","n/a",H14*I14) -> n/a | T14: =IF(S14="n/a","n/a",IF(R14>S14,1,0)) -> n/a
A15: Mullins | B15: 31.26 | C15: -41.1 | D15: 2.72 | E15: 43.28 | F15: 5980 | G15: 0.0259 | H15: n/a | I15: n/a | J15: n/a | K15: 9.47e-11 | L15: 0.2415 | M15: n/a | N15: =IF(H15="n/a","n/a",IF(E15>H15,1,0)) -> n/a | O15: =IF(I15="n/a","n/a",IF(F15>I15,1,0)) -> n/a | P15: =IF(J15="n/a","n/a",IF(G15>J15,1,0)) -> n/a | Q15: =IF(M15="n/a","n/a",IF(L15>M15,1,0)) -> n/a | R15: =E15*F15 -> 258814.4 | S15: =IF(H15="n/a","n/a",H15*I15) -> n/a | T15: =IF(S15="n/a","n/a",IF(R15>S15,1,0)) -> n/a
A16: GISP2 | B16: 505 | C16: -40 | D16: 3.12 | E16: 73.2 | F16: 1840 | G16: 0 | H16: 114 | I16: 326.35 | J16: 0 | K16: 6.38e-09 | L16: 0.219 | M16: 0.2767 | N16: =IF(H16="n/a","n/a",IF(E16>H16,1,0)) -> 0 | O16: =IF(I16="n/a","n/a",IF(F16>I16,1,0)) -> 1 | P16: =IF(J16="n/a","n/a",IF(G16>J16,1,0)) -> 0 | Q16: =IF(M16="n/a","n/a",IF(L16>M16,1,0)) -> 0 | R16: =E16*F16 -> 134688 | S16: =IF(H16="n/a","n/a",H16*I16) -> 37203.9 | T16: =IF(S16="n/a","n/a",IF(R16>S16,1,0)) -> 1
A17: GISP2 | B17: 1404 | C17: -40.7 | D17: 2.58 | E17: 97.6 | F17: 1170 | G17: 0 | H17: n/a | I17: n/a | J17: n/a | K17: 2.6e-08 | L17: 0.1705 | M17: 0.2212 | N17: =IF(H17="n/a","n/a",IF(E17>H17,1,0)) -> n/a | O17: =IF(I17="n/a","n/a",IF(F17>I17,1,0)) -> n/a | P17: =IF(J17="n/a","n/a",IF(G17>J17,1,0)) -> n/a | Q17: =IF(M17="n/a","n/a",IF(L17>M17,1,0)) -> 0 | R17: =E17*F17 -> 114192 | S17: =IF(H17="n/a","n/a",H17*I17) -> n/a | T17: =IF(S17="n/a","n/a",IF(R17>S17,1,0)) -> n/a
A18: GISP2 | B18: 1406 | C18: -40.6 | D18: 2.98 | E18: 35.47 | F18: 2600 | G18: 0 | H18: 47.05 | I18: 514.6 | J18: 0 | K18: 6.89e-10 | L18: 0.115 | M18: 0.1356 | N18: =IF(H18="n/a","n/a",IF(E18>H18,1,0)) -> 0 | O18: =IF(I18="n/a","n/a",IF(F18>I18,1,0)) -> 1 | P18: =IF(J18="n/a","n/a",IF(G18>J18,1,0)) -> 0 | Q18: =IF(M18="n/a","n/a",IF(L18>M18,1,0)) -> 0 | R18: =E18*F18 -> 92222 | S18: =IF(H18="n/a","n/a",H18*I18) -> 24211.93 | T18: =IF(S18="n/a","n/a",IF(R18>S18,1,0)) -> 1
A19: GISP2 | B19: 1710 | C19: -40 | D19: 3.04 | E19: 27.5 | F19: 1050 | G19: 0 | H19: 14.7 | I19: 278.1 | J19: 0.12 | K19: n/a | L19: 0.178 | M19: 0.1795 | N19: =IF(H19="n/a","n/a",IF(E19>H19,1,0)) -> 1 | O19: =IF(I19="n/a","n/a",IF(F19>I19,1,0)) -> 1 | P19: =IF(J19="n/a","n/a",IF(G19>J19,1,0)) -> 0 | Q19: =IF(M19="n/a","n/a",IF(L19>M19,1,0)) -> 0 | R19: =E19*F19 -> 28875 | S19: =IF(H19="n/a","n/a",H19*I19) -> 4088.07 | T19: =IF(S19="n/a","n/a",IF(R19>S19,1,0)) -> 1
A20: GISP2 | B20: 1792 | C20: -40.1 | D20: 3.44 | E20: 76.78 | F20: 747 | G20: 0 | H20: 178.31 | I20: 86.8 | J20: 0.01 | K20: 5.18e-09 | L20: 0.205 | M20: 0.2578 | N20: =IF(H20="n/a","n/a",IF(E20>H20,1,0)) -> 0 | O20: =IF(I20="n/a","n/a",IF(F20>I20,1,0)) -> 1 | P20: =IF(J20="n/a","n/a",IF(G20>J20,1,0)) -> 0 | Q20: =IF(M20="n/a","n/a",IF(L20>M20,1,0)) -> 0 | R20: =E20*F20 -> 57354.66 | S20: =IF(H20="n/a","n/a",H20*I20) -> 15477.308 | T20: =IF(S20="n/a","n/a",IF(R20>S20,1,0)) -> 1
A21: GISP2 | B21: 2550 | C21: -40.1 | D21: 3.11 | E21: 83.4 | F21: 769 | G21: 0 | H21: n/a | I21: n/a | J21: n/a | K21: 1.37e-09 | L21: 0.1858 | M21: n/a | N21: =IF(H21="n/a","n/a",IF(E21>H21,1,0)) -> n/a | O21: =IF(I21="n/a","n/a",IF(F21>I21,1,0)) -> n/a | P21: =IF(J21="n/a","n/a",IF(G21>J21,1,0)) -> n/a | Q21: =IF(M21="n/a","n/a",IF(L21>M21,1,0)) -> n/a | R21: =E21*F21 -> 64134.6 | S21: =IF(H21="n/a","n/a",H21*I21) -> n/a | T21: =IF(S21="n/a","n/a",IF(R21>S21,1,0)) -> n/a
A22: Newall | B22: 55 | C22: -40.4 | D22: 3.03 | E22: 35.5 | F22: 4090 | G22: 0 | H22: 16.2 | I22: 473.97 | J22: 0 | K22: 6.8e-09 | L22: 0.2078 | M22: 0.2996 | N22: =IF(H22="n/a","n/a",IF(E22>H22,1,0)) -> 1 | O22: =IF(I22="n/a","n/a",IF(F22>I22,1,0)) -> 1 | P22: =IF(J22="n/a","n/a",IF(G22>J22,1,0)) -> 0 | Q22: =IF(M22="n/a","n/a",IF(L22>M22,1,0)) -> 0 | R22: =E22*F22 -> 145195 | S22: =IF(H22="n/a","n/a",H22*I22) -> 7678.314 | T22: =IF(S22="n/a","n/a",IF(R22>S22,1,0)) -> 1
A23: Newall | B23: 80.3 | C23: -40.3 | D23: 2.86 | E23: 86.2 | F23: 1640 | G23: 0 | H23: 61.7 | I23: 234.3 | J23: 0.11 | K23: 1.3e-09 | L23: 0.1975 | M23: 0.271 | N23: =IF(H23="n/a","n/a",IF(E23>H23,1,0)) -> 1 | O23: =IF(I23="n/a","n/a",IF(F23>I23,1,0)) -> 1 | P23: =IF(J23="n/a","n/a",IF(G23>J23,1,0)) -> 0 | Q23: =IF(M23="n/a","n/a",IF(L23>M23,1,0)) -> 0 | R23: =E23*F23 -> 141368 | S23: =IF(H23="n/a","n/a",H23*I23) -> 14456.31 | T23: =IF(S23="n/a","n/a",IF(R23>S23,1,0)) -> 1
A24: Newall | B24: 102 | C24: -44.8 | D24: 2.56 | E24: 70.6525 | F24: 1060 | G24: 0 | H24: 232.1869 | I24: 90.7415 | J24: 0.0676 | K24: n/a | L24: 0.25 | M24: 0.2311 | N24: =IF(H24="n/a","n/a",IF(E24>H24,1,0)) -> 0 | O24: =IF(I24="n/a","n/a",IF(F24>I24,1,0)) -> 1 | P24: =IF(J24="n/a","n/a",IF(G24>J24,1,0)) -> 0 | Q24: =IF(M24="n/a","n/a",IF(L24>M24,1,0)) -> 1 | R24: =E24*F24 -> 74891.65 | S24: =IF(H24="n/a","n/a",H24*I24) -> 21068.988 | T24: =IF(S24="n/a","n/a",IF(R24>S24,1,0)) -> 1
A25: Newall | B25: 120 | C25: -40.3 | D25: 3.08 | E25: 77.5 | F25: 2790 | G25: 0 | H25: 8.8 | I25: 242.6 | J25: 0 | K25: n/a | L25: 0.2139 | M25: 0.198 | N25: =IF(H25="n/a","n/a",IF(E25>H25,1,0)) -> 1 | O25: =IF(I25="n/a","n/a",IF(F25>I25,1,0)) -> 1 | P25: =IF(J25="n/a","n/a",IF(G25>J25,1,0)) -> 0 | Q25: =IF(M25="n/a","n/a",IF(L25>M25,1,0)) -> 1 | R25: =E25*F25 -> 216225 | S25: =IF(H25="n/a","n/a",H25*I25) -> 2134.88 | T25: =IF(S25="n/a","n/a",IF(R25>S25,1,0)) -> 1
A26: Newall | B26: 133 | C26: -40.5 | D26: 2.88 | E26: 67.05 | F26: 1240 | G26: 0 | H26: 144.52 | I26: 10.96 | J26: 0.2 | K26: 8.45e-10 | L26: 0.23 | M26: n/a | N26: =IF(H26="n/a","n/a",IF(E26>H26,1,0)) -> 0 | O26: =IF(I26="n/a","n/a",IF(F26>I26,1,0)) -> 1 | P26: =IF(J26="n/a","n/a",IF(G26>J26,1,0)) -> 0 | Q26: =IF(M26="n/a","n/a",IF(L26>M26,1,0)) -> n/a | R26: =E26*F26 -> 83142 | S26: =IF(H26="n/a","n/a",H26*I26) -> 1583.9392 | T26: =IF(S26="n/a","n/a",IF(R26>S26,1,0)) -> 1
A27: Siple Dome | B27: 54.95 | C27: -40.2 | D27: 2.68 | E27: 61.1 | F27: 2670 | G27: 0 | H27: 57.3 | I27: 278.3 | J27: 0.085 | K27: 2.48e-09 | L27: 0.2411 | M27: 0.2634 | N27: =IF(H27="n/a","n/a",IF(E27>H27,1,0)) -> 1 | O27: =IF(I27="n/a","n/a",IF(F27>I27,1,0)) -> 1 | P27: =IF(J27="n/a","n/a",IF(G27>J27,1,0)) -> 0 | Q27: =IF(M27="n/a","n/a",IF(L27>M27,1,0)) -> 0 | R27: =E27*F27 -> 163137 | S27: =IF(H27="n/a","n/a",H27*I27) -> 15946.59 | T27: =IF(S27="n/a","n/a",IF(R27>S27,1,0)) -> 1
A28: Siple Dome | B28: 185.35 | C28: -40.3 | D28: 3 | E28: 70 | F28: 7160 | G28: 0.02 | H28: n/a | I28: n/a | J28: n/a | K28: 2.22e-10 | L28: 0.2921 | M28: n/a | N28: =IF(H28="n/a","n/a",IF(E28>H28,1,0)) -> n/a | O28: =IF(I28="n/a","n/a",IF(F28>I28,1,0)) -> n/a | P28: =IF(J28="n/a","n/a",IF(G28>J28,1,0)) -> n/a | Q28: =IF(M28="n/a","n/a",IF(L28>M28,1,0)) -> n/a | R28: =E28*F28 -> 501200 | S28: =IF(H28="n/a","n/a",H28*I28) -> n/a | T28: =IF(S28="n/a","n/a",IF(R28>S28,1,0)) -> n/a
A29: Siple Dome | B29: 558.75 | C29: -41.4 | D29: 3 | E29: 244.8 | F29: 401.8 | G29: 0 | H29: 390.4 | I29: 42.6 | J29: 0.039 | K29: 8.47e-09 | L29: 0.173 | M29: 0.229 | N29: =IF(H29="n/a","n/a",IF(E29>H29,1,0)) -> 0 | O29: =IF(I29="n/a","n/a",IF(F29>I29,1,0)) -> 1 | P29: =IF(J29="n/a","n/a",IF(G29>J29,1,0)) -> 0 | Q29: =IF(M29="n/a","n/a",IF(L29>M29,1,0)) -> 0 | R29: =E29*F29 -> 98360.64 | S29: =IF(H29="n/a","n/a",H29*I29) -> 16631.04 | T29: =IF(S29="n/a","n/a",IF(R29>S29,1,0)) -> 1
A30: Siple Dome | B30: 719.24 | C30: -44 | D30: 2.98 | E30: 33.1 | F30: 3280 | G30: 0 | H30: 16.2 | I30: 335.6 | J30: 0.053 | K30: 3.81e-09 | L30: 0.214 | M30: 0.242 | N30: =IF(H30="n/a","n/a",IF(E30>H30,1,0)) -> 1 | O30: =IF(I30="n/a","n/a",IF(F30>I30,1,0)) -> 1 | P30: =IF(J30="n/a","n/a",IF(G30>J30,1,0)) -> 0 | Q30: =IF(M30="n/a","n/a",IF(L30>M30,1,0)) -> 0 | R30: =E30*F30 -> 108568 | S30: =IF(H30="n/a","n/a",H30*I30) -> 5436.72 | T30: =IF(S30="n/a","n/a",IF(R30>S30,1,0)) -> 1
A31: Siple Dome | B31: 1004 | C31: -40.8 | D31: 2.83 | E31: 9.9 | F31: 2560 | G31: 0 | H31: 10.4 | I31: 464.8 | J31: 0.1 | K31: 2.9e-10 | L31: 0.178 | M31: 0.181 | N31: =IF(H31="n/a","n/a",IF(E31>H31,1,0)) -> 0 | O31: =IF(I31="n/a","n/a",IF(F31>I31,1,0)) -> 1 | P31: =IF(J31="n/a","n/a",IF(G31>J31,1,0)) -> 0 | Q31: =IF(M31="n/a","n/a",IF(L31>M31,1,0)) -> 0 | R31: =E31*F31 -> 25344 | S31: =IF(H31="n/a","n/a",H31*I31) -> 4833.92 | T31: =IF(S31="n/a","n/a",IF(R31>S31,1,0)) -> 1
A32: South Pole | B32: 51 | C32: -40.4 | D32: 2.38 | E32: 77.8 | F32: 1040 | G32: 0 | H32: 15.5 | I32: 113.2 | J32: 0.1958 | K32: 8.9e-11 | L32: 0.161 | M32: 0.1533 | N32: =IF(H32="n/a","n/a",IF(E32>H32,1,0)) -> 1 | O32: =IF(I32="n/a","n/a",IF(F32>I32,1,0)) -> 1 | P32: =IF(J32="n/a","n/a",IF(G32>J32,1,0)) -> 0 | Q32: =IF(M32="n/a","n/a",IF(L32>M32,1,0)) -> 1 | R32: =E32*F32 -> 80912 | S32: =IF(H32="n/a","n/a",H32*I32) -> 1754.6 | T32: =IF(S32="n/a","n/a",IF(R32>S32,1,0)) -> 1
A33: South Pole | B33: 69.9 | C33: -40.3 | D33: 2.49 | E33: 54.2 | F33: 1760 | G33: 0 | H33: 26.1 | I33: 402.29 | J33: 0.12 | K33: n/a | L33: 0.1734 | M33: 0.2747 | N33: =IF(H33="n/a","n/a",IF(E33>H33,1,0)) -> 1 | O33: =IF(I33="n/a","n/a",IF(F33>I33,1,0)) -> 1 | P33: =IF(J33="n/a","n/a",IF(G33>J33,1,0)) -> 0 | Q33: =IF(M33="n/a","n/a",IF(L33>M33,1,0)) -> 0 | R33: =E33*F33 -> 95392 | S33: =IF(H33="n/a","n/a",H33*I33) -> 10499.769 | T33: =IF(S33="n/a","n/a",IF(R33>S33,1,0)) -> 1
A34: South Pole | B34: 89 | C34: -40.4 | D34: 2.65 | E34: 51.2 | F34: 1840 | G34: 0.01 | H34: 13.8 | I34: 207.58 | J34: 0.19 | K34: n/a | L34: 0.1807 | M34: 0.2348 | N34: =IF(H34="n/a","n/a",IF(E34>H34,1,0)) -> 1 | O34: =IF(I34="n/a","n/a",IF(F34>I34,1,0)) -> 1 | P34: =IF(J34="n/a","n/a",IF(G34>J34,1,0)) -> 0 | Q34: =IF(M34="n/a","n/a",IF(L34>M34,1,0)) -> 0 | R34: =E34*F34 -> 94208 | S34: =IF(H34="n/a","n/a",H34*I34) -> 2864.604 | T34: =IF(S34="n/a","n/a",IF(R34>S34,1,0)) -> 1
A35: South Pole | B35: 92 | C35: -40.2 | D35: 2.43 | E35: 78 | F35: 465 | G35: 0.05 | H35: n/a | I35: n/a | J35: n/a | K35: 1.74e-09 | L35: 0.1866 | M35: 0.2409 | N35: =IF(H35="n/a","n/a",IF(E35>H35,1,0)) -> n/a | O35: =IF(I35="n/a","n/a",IF(F35>I35,1,0)) -> n/a | P35: =IF(J35="n/a","n/a",IF(G35>J35,1,0)) -> n/a | Q35: =IF(M35="n/a","n/a",IF(L35>M35,1,0)) -> 0 | R35: =E35*F35 -> 36270 | S35: =IF(H35="n/a","n/a",H35*I35) -> n/a | T35: =IF(S35="n/a","n/a",IF(R35>S35,1,0)) -> n/a
A36: Taylor Dome | B36: 102.11 | C36: -40.4 | D36: 2.75 | E36: 61.22 | F36: 1250 | G36: 0.0851 | H36: n/a | I36: n/a | J36: n/a | K36: 2.33e-10 | L36: 0.1876 | M36: 0.2875 | N36: =IF(H36="n/a","n/a",IF(E36>H36,1,0)) -> n/a | O36: =IF(I36="n/a","n/a",IF(F36>I36,1,0)) -> n/a | P36: =IF(J36="n/a","n/a",IF(G36>J36,1,0)) -> n/a | Q36: =IF(M36="n/a","n/a",IF(L36>M36,1,0)) -> 0 | R36: =E36*F36 -> 76525 | S36: =IF(H36="n/a","n/a",H36*I36) -> n/a | T36: =IF(S36="n/a","n/a",IF(R36>S36,1,0)) -> n/a
A37: Taylor Dome | B37: 374.89 | C37: -40.3 | D37: 2.79 | E37: 27.4 | F37: 4170 | G37: 0 | H37: 14.29 | I37: 230.1 | J37: 0.19 | K37: 7.99e-11 | L37: 0.2133 | M37: 0.3 | N37: =IF(H37="n/a","n/a",IF(E37>H37,1,0)) -> 1 | O37: =IF(I37="n/a","n/a",IF(F37>I37,1,0)) -> 1 | P37: =IF(J37="n/a","n/a",IF(G37>J37,1,0)) -> 0 | Q37: =IF(M37="n/a","n/a",IF(L37>M37,1,0)) -> 0 | R37: =E37*F37 -> 114258 | S37: =IF(H37="n/a","n/a",H37*I37) -> 3288.129 | T37: =IF(S37="n/a","n/a",IF(R37>S37,1,0)) -> 1
A38: Taylor Dome | B38: 543.97 | C38: -40.3 | D38: 2.91 | E38: 59.2 | F38: 1780 | G38: 0 | H38: 22.2 | I38: 211.3 | J38: 0.08 | K38: 3.45e-10 | L38: 0.206 | M38: 0.2575 | N38: =IF(H38="n/a","n/a",IF(E38>H38,1,0)) -> 1 | O38: =IF(I38="n/a","n/a",IF(F38>I38,1,0)) -> 1 | P38: =IF(J38="n/a","n/a",IF(G38>J38,1,0)) -> 0 | Q38: =IF(M38="n/a","n/a",IF(L38>M38,1,0)) -> 0 | R38: =E38*F38 -> 105376 | S38: =IF(H38="n/a","n/a",H38*I38) -> 4690.86 | T38: =IF(S38="n/a","n/a",IF(R38>S38,1,0)) -> 1
A39: Vostok (Meteoric) | B39: 429 | C39: -40.3 | D39: 2.96 | E39: 88.6 | F39: 1300 | G39: 0 | H39: 176.8 | I39: 106.5 | J39: 0 | K39: 9.68e-09 | L39: 0.204 | M39: 0.27 | N39: =IF(H39="n/a","n/a",IF(E39>H39,1,0)) -> 0 | O39: =IF(I39="n/a","n/a",IF(F39>I39,1,0)) -> 1 | P39: =IF(J39="n/a","n/a",IF(G39>J39,1,0)) -> 0 | Q39: =IF(M39="n/a","n/a",IF(L39>M39,1,0)) -> 0 | R39: =E39*F39 -> 115180 | S39: =IF(H39="n/a","n/a",H39*I39) -> 18829.2 | T39: =IF(S39="n/a","n/a",IF(R39>S39,1,0)) -> 1
A40: Vostok (Meteoric) | B40: 2044 | C40: -40.4 | D40: 2.97 | E40: 54.8 | F40: 2390 | G40: 0 | H40: 42.6 | I40: 361.2 | J40: 0.04 | K40: 1.02e-09 | L40: 0.1933 | M40: 0.283 | N40: =IF(H40="n/a","n/a",IF(E40>H40,1,0)) -> 1 | O40: =IF(I40="n/a","n/a",IF(F40>I40,1,0)) -> 1 | P40: =IF(J40="n/a","n/a",IF(G40>J40,1,0)) -> 0 | Q40: =IF(M40="n/a","n/a",IF(L40>M40,1,0)) -> 0 | R40: =E40*F40 -> 130972 | S40: =IF(H40="n/a","n/a",H40*I40) -> 15387.12 | T40: =IF(S40="n/a","n/a",IF(R40>S40,1,0)) -> 1
...

Sheet Mean Parameters
A1: Temp © | B1: eps_inf | C1: delta_eps1 | D1: fr1 (Hz) | E1: alpha1 | F1: delta_eps2 | G1: fr2 (Hz) | H1: alpha2 | I1: sigmaDC | J1: Ea1 | K1: Ea2 | L1: eps1 | M1: eps2
A2: =AVERAGE('Grimm et al. (2015)'!C2:C50) -> -40.597959 | B2: =AVERAGE('Grimm et al. (2015)'!D2:D50) -> 2.9008163 | C2: =AVERAGE('Grimm et al. (2015)'!E2:E50) -> 67.974541 | D2: =AVERAGE('Grimm et al. (2015)'!F2:F50) -> 2748.4912 | E2: =AVERAGE('Grimm et al. (2015)'!G2:G50) -> 0.018073469 | F2: =AVERAGE('Grimm et al. (2015)'!H2:H50) -> 74.568033 | G2: =AVERAGE('Grimm et al. (2015)'!I2:I50) -> 330.80819 | H2: =AVERAGE('Grimm et al. (2015)'!J2:J50) -> 0.066585185 | ... K2: =AVERAGE('Grimm et al. (2015)'!M2:M50) -> 0.26329333 | L2: =C2+B2 -> 70.875357 | M2: =F2+B2 -> 77.46885
